[0.000000] (-) TimerEvent: {}
[0.000117] (pacr_solutions) JobQueued: {'identifier': 'pacr_solutions', 'dependencies': OrderedDict()}
[0.000175] (pacr_solutions) JobStarted: {'identifier': 'pacr_solutions'}
[0.097976] (-) TimerEvent: {}
[0.198342] (-) TimerEvent: {}
[0.298626] (-) TimerEvent: {}
[0.399364] (-) TimerEvent: {}
[0.446277] (pacr_solutions) StderrLine: {'line': b'Traceback (most recent call last):\n  File "/usr/lib/python3/dist-packages/colcon_parallel_executor/executor/parallel.py", line 75, in execute\n    loop.run_until_complete(future)\n  File "/usr/lib/python3.8/asyncio/base_events.py", line 603, in run_until_complete\n    self.run_forever()\n  File "/usr/lib/python3.8/asyncio/base_events.py", line 570, in run_forever\n    self._run_once()\n  File "/usr/lib/python3.8/asyncio/base_events.py", line 1823, in _run_once\n    event_list = self._selector.select(timeout)\n  File "/usr/lib/python3.8/selectors.py", line 468, in select\n    fd_event_list = self._selector.poll(timeout, max_ev)\nKeyboardInterrupt\n\nDuring handling of the above exception, another exception occurred:\n\nTraceback (most recent call last):\n  File "/usr/lib/python3/dist-packages/colcon_core/executor/__init__.py", line 91, in __call__\n    rc = await self.task(*args, **kwargs)\n  File "/usr/lib/python3/dist-packages/colcon_core/task/__init__.py", line 93, in __call__\n    return await task_method(*args, **kwargs)\n  File "/usr/lib/python3/dist-packages/colcon_ros/task/ament_python/build.py", line 102, in build\n    return await extension.build(additional_hooks=additional_hooks)\n  File "/usr/lib/python3/dist-packages/colcon_core/task/python/build.py", line 94, in build\n    available_commands = await self._get_available_commands(\n  File "/usr/lib/python3/dist-packages/colcon_core/task/python/build.py", line 192, in _get_available_commands\n    output = await check_output(\n  File "/usr/lib/python3/dist-packages/colcon_core/subprocess.py", line 129, in check_output\n    assert not rc, f\'Expected {args} to pass: {stderr_data}\'\nAssertionError: Expected [\'/usr/bin/python3\', \'-W\', \'ignore:setup.py install is deprecated\', \'setup.py\', \'--help-commands\'] to pass: Fatal Python error: init_import_size: Failed to import the site module\nPython runtime state: initialized\nTraceback (most recent call last):\n  File "/usr/lib/python3.8/site.py", line 597, in <module>\n    main()\n  File "/usr/lib/python3.8/site.py", line 584, in main\n    known_paths = addsitepackages(known_paths)\n  File "/usr/lib/python3.8/site.py", line 367, in addsitepackages\n    addsitedir(sitedir, known_paths)\n  File "/usr/lib/python3.8/site.py", line 214, in addsitedir\n    addpackage(sitedir, name, known_paths)\n  File "/usr/lib/python3.8/site.py", line 175, in addpackage\n    exec(line)\n  File "<string>", line 1, in <module>\n  File "<string>", line 1, in <module>\nKeyboardInterrupt\n\n'}
[0.456547] (pacr_solutions) JobEnded: {'identifier': 'pacr_solutions', 'rc': 'SIGINT'}
[0.466960] (-) EventReactorShutdown: {}
